[32mINFO    [0m custom_logger:test_login_ddt.py:13 ************** Test002DDTLogin Started *************
[32mINFO    [0m custom_logger:test_login_ddt.py:14 ************** Test Login DDT Started *************
[33mWARNING [0m urllib3.connectionpool:connectionpool.py:874 Retrying (Retry(total=2, connect=None, read=None, redirect=None, status=None)) after connection broken by 'NewConnectionError('<urllib3.connection.HTTPConnection object at 0x00000285FEBBF2C0>: Failed to establish a new connection: [WinError 10061] Aucune connexion nâ€™a pu Ãªtre Ã©tablie car lâ€™ordinateur cible lâ€™a expressÃ©ment refusÃ©e')': /session/f35a4a99133c196ecf32ae094af3533a/url
[33mWARNING [0m urllib3.connectionpool:connectionpool.py:874 Retrying (Retry(total=1, connect=None, read=None, redirect=None, status=None)) after connection broken by 'NewConnectionError('<urllib3.connection.HTTPConnection object at 0x00000285FEBBF0E0>: Failed to establish a new connection: [WinError 10061] Aucune connexion nâ€™a pu Ãªtre Ã©tablie car lâ€™ordinateur cible lâ€™a expressÃ©ment refusÃ©e')': /session/f35a4a99133c196ecf32ae094af3533a/url
[33mWARNING [0m urllib3.connectionpool:connectionpool.py:874 Retrying (Retry(total=0, connect=None, read=None, redirect=None, status=None)) after connection broken by 'NewConnectionError('<urllib3.connection.HTTPConnection object at 0x00000285FEBBF650>: Failed to establish a new connection: [WinError 10061] Aucune connexion nâ€™a pu Ãªtre Ã©tablie car lâ€™ordinateur cible lâ€™a expressÃ©ment refusÃ©e')': /session/f35a4a99133c196ecf32ae094af3533a/url